=================running cronjob=====================
=================running cronjob=====================
updating noshow counts for {}
Traceback (most recent call last):
  File "/ReservationAPI/noshow.py", line 6, in <module>
    from service import model_config, api_config
ImportError: cannot import name 'model_config' from 'service' (/ReservationAPI/service.py)
=================running cronjob=====================
updating noshow counts for {}
Traceback (most recent call last):
  File "/usr/local/lib/python3.10/site-packages/pymysql/connections.py", line 616, in connect
    sock = socket.create_connection(
  File "/usr/local/lib/python3.10/socket.py", line 845, in create_connection
    raise err
  File "/usr/local/lib/python3.10/socket.py", line 833, in create_connection
    sock.connect(sa)
OSError: [Errno 99] Cannot assign requested address

During handling of the above exception, another exception occurred:

Traceback (most recent call last):
  File "/usr/local/lib/python3.10/site-packages/sqlalchemy/engine/base.py", line 145, in __init__
    self._dbapi_connection = engine.raw_connection()
  File "/usr/local/lib/python3.10/site-packages/sqlalchemy/engine/base.py", line 3275, in raw_connection
    return self.pool.connect()
  File "/usr/local/lib/python3.10/site-packages/sqlalchemy/pool/base.py", line 455, in connect
    return _ConnectionFairy._checkout(self)
  File "/usr/local/lib/python3.10/site-packages/sqlalchemy/pool/base.py", line 1271, in _checkout
    fairy = _ConnectionRecord.checkout(pool)
  File "/usr/local/lib/python3.10/site-packages/sqlalchemy/pool/base.py", line 719, in checkout
    rec = pool._do_get()
  File "/usr/local/lib/python3.10/site-packages/sqlalchemy/pool/impl.py", line 168, in _do_get
    with util.safe_reraise():
  File "/usr/local/lib/python3.10/site-packages/sqlalchemy/util/langhelpers.py", line 147, in __exit__
    raise exc_value.with_traceback(exc_tb)
  File "/usr/local/lib/python3.10/site-packages/sqlalchemy/pool/impl.py", line 166, in _do_get
    return self._create_connection()
  File "/usr/local/lib/python3.10/site-packages/sqlalchemy/pool/base.py", line 396, in _create_connection
    return _ConnectionRecord(self)
  File "/usr/local/lib/python3.10/site-packages/sqlalchemy/pool/base.py", line 681, in __init__
    self.__connect()
  File "/usr/local/lib/python3.10/site-packages/sqlalchemy/pool/base.py", line 905, in __connect
    with util.safe_reraise():
  File "/usr/local/lib/python3.10/site-packages/sqlalchemy/util/langhelpers.py", line 147, in __exit__
    raise exc_value.with_traceback(exc_tb)
  File "/usr/local/lib/python3.10/site-packages/sqlalchemy/pool/base.py", line 901, in __connect
    self.dbapi_connection = connection = pool._invoke_creator(self)
  File "/usr/local/lib/python3.10/site-packages/sqlalchemy/engine/create.py", line 636, in connect
    return dialect.connect(*cargs, **cparams)
  File "/usr/local/lib/python3.10/site-packages/sqlalchemy/engine/default.py", line 580, in connect
    return self.loaded_dbapi.connect(*cargs, **cparams)
  File "/usr/local/lib/python3.10/site-packages/pymysql/connections.py", line 352, in __init__
    self.connect()
  File "/usr/local/lib/python3.10/site-packages/pymysql/connections.py", line 668, in connect
    raise exc
pymysql.err.OperationalError: (2003, "Can't connect to MySQL server on 'localhost' ([Errno 99] Cannot assign requested address)")

The above exception was the direct cause of the following exception:

Traceback (most recent call last):
  File "/ReservationAPI/noshow.py", line 82, in <module>
    no_show_check = NoShowCheck()
  File "/ReservationAPI/noshow.py", line 15, in __init__
    Service.__init__(
  File "/ReservationAPI/service.py", line 180, in __init__
    self.init_orm(model_config)
  File "/ReservationAPI/service.py", line 209, in init_orm
    ORM_BASE.prepare(autoload_with=ORM_ENGINE, reflect=True)
  File "<string>", line 2, in prepare
  File "/usr/local/lib/python3.10/site-packages/sqlalchemy/util/deprecations.py", line 277, in warned
    return fn(*args, **kwargs)  # type: ignore[no-any-return]
  File "/usr/local/lib/python3.10/site-packages/sqlalchemy/ext/automap.py", line 1230, in prepare
    cls.metadata.reflect(autoload_with, **opts)  # type: ignore[arg-type]  # noqa: E501
  File "/usr/local/lib/python3.10/site-packages/sqlalchemy/sql/schema.py", line 5475, in reflect
    with inspection.inspect(bind)._inspection_context() as insp:
  File "/usr/local/lib/python3.10/site-packages/sqlalchemy/inspection.py", line 111, in inspect
    ret = reg(subject)
  File "/usr/local/lib/python3.10/site-packages/sqlalchemy/engine/reflection.py", line 304, in _engine_insp
    return Inspector._construct(Inspector._init_engine, bind)
  File "/usr/local/lib/python3.10/site-packages/sqlalchemy/engine/reflection.py", line 237, in _construct
    init(self, bind)
  File "/usr/local/lib/python3.10/site-packages/sqlalchemy/engine/reflection.py", line 248, in _init_engine
    engine.connect().close()
  File "/usr/local/lib/python3.10/site-packages/sqlalchemy/engine/base.py", line 3251, in connect
    return self._connection_cls(self)
  File "/usr/local/lib/python3.10/site-packages/sqlalchemy/engine/base.py", line 147, in __init__
    Connection._handle_dbapi_exception_noconnection(
  File "/usr/local/lib/python3.10/site-packages/sqlalchemy/engine/base.py", line 2413, in _handle_dbapi_exception_noconnection
    raise sqlalchemy_exception.with_traceback(exc_info[2]) from e
  File "/usr/local/lib/python3.10/site-packages/sqlalchemy/engine/base.py", line 145, in __init__
    self._dbapi_connection = engine.raw_connection()
  File "/usr/local/lib/python3.10/site-packages/sqlalchemy/engine/base.py", line 3275, in raw_connection
    return self.pool.connect()
  File "/usr/local/lib/python3.10/site-packages/sqlalchemy/pool/base.py", line 455, in connect
    return _ConnectionFairy._checkout(self)
  File "/usr/local/lib/python3.10/site-packages/sqlalchemy/pool/base.py", line 1271, in _checkout
    fairy = _ConnectionRecord.checkout(pool)
  File "/usr/local/lib/python3.10/site-packages/sqlalchemy/pool/base.py", line 719, in checkout
    rec = pool._do_get()
  File "/usr/local/lib/python3.10/site-packages/sqlalchemy/pool/impl.py", line 168, in _do_get
    with util.safe_reraise():
  File "/usr/local/lib/python3.10/site-packages/sqlalchemy/util/langhelpers.py", line 147, in __exit__
    raise exc_value.with_traceback(exc_tb)
  File "/usr/local/lib/python3.10/site-packages/sqlalchemy/pool/impl.py", line 166, in _do_get
    return self._create_connection()
  File "/usr/local/lib/python3.10/site-packages/sqlalchemy/pool/base.py", line 396, in _create_connection
    return _ConnectionRecord(self)
  File "/usr/local/lib/python3.10/site-packages/sqlalchemy/pool/base.py", line 681, in __init__
    self.__connect()
  File "/usr/local/lib/python3.10/site-packages/sqlalchemy/pool/base.py", line 905, in __connect
    with util.safe_reraise():
  File "/usr/local/lib/python3.10/site-packages/sqlalchemy/util/langhelpers.py", line 147, in __exit__
    raise exc_value.with_traceback(exc_tb)
  File "/usr/local/lib/python3.10/site-packages/sqlalchemy/pool/base.py", line 901, in __connect
    self.dbapi_connection = connection = pool._invoke_creator(self)
  File "/usr/local/lib/python3.10/site-packages/sqlalchemy/engine/create.py", line 636, in connect
    return dialect.connect(*cargs, **cparams)
  File "/usr/local/lib/python3.10/site-packages/sqlalchemy/engine/default.py", line 580, in connect
    return self.loaded_dbapi.connect(*cargs, **cparams)
  File "/usr/local/lib/python3.10/site-packages/pymysql/connections.py", line 352, in __init__
    self.connect()
  File "/usr/local/lib/python3.10/site-packages/pymysql/connections.py", line 668, in connect
    raise exc
sqlalchemy.exc.OperationalError: (pymysql.err.OperationalError) (2003, "Can't connect to MySQL server on 'localhost' ([Errno 99] Cannot assign requested address)")
(Background on this error at: https://sqlalche.me/e/20/e3q8)
Traceback (most recent call last):
  File "/usr/local/lib/python3.10/site-packages/pymysql/connections.py", line 616, in connect
    sock = socket.create_connection(
  File "/usr/local/lib/python3.10/socket.py", line 845, in create_connection
    raise err
  File "/usr/local/lib/python3.10/socket.py", line 833, in create_connection
    sock.connect(sa)
OSError: [Errno 99] Cannot assign requested address

During handling of the above exception, another exception occurred:

Traceback (most recent call last):
  File "/usr/local/lib/python3.10/site-packages/sqlalchemy/engine/base.py", line 145, in __init__
    self._dbapi_connection = engine.raw_connection()
  File "/usr/local/lib/python3.10/site-packages/sqlalchemy/engine/base.py", line 3275, in raw_connection
    return self.pool.connect()
  File "/usr/local/lib/python3.10/site-packages/sqlalchemy/pool/base.py", line 455, in connect
    return _ConnectionFairy._checkout(self)
  File "/usr/local/lib/python3.10/site-packages/sqlalchemy/pool/base.py", line 1271, in _checkout
    fairy = _ConnectionRecord.checkout(pool)
  File "/usr/local/lib/python3.10/site-packages/sqlalchemy/pool/base.py", line 719, in checkout
    rec = pool._do_get()
  File "/usr/local/lib/python3.10/site-packages/sqlalchemy/pool/impl.py", line 168, in _do_get
    with util.safe_reraise():
  File "/usr/local/lib/python3.10/site-packages/sqlalchemy/util/langhelpers.py", line 147, in __exit__
    raise exc_value.with_traceback(exc_tb)
  File "/usr/local/lib/python3.10/site-packages/sqlalchemy/pool/impl.py", line 166, in _do_get
    return self._create_connection()
  File "/usr/local/lib/python3.10/site-packages/sqlalchemy/pool/base.py", line 396, in _create_connection
    return _ConnectionRecord(self)
  File "/usr/local/lib/python3.10/site-packages/sqlalchemy/pool/base.py", line 681, in __init__
    self.__connect()
  File "/usr/local/lib/python3.10/site-packages/sqlalchemy/pool/base.py", line 905, in __connect
    with util.safe_reraise():
  File "/usr/local/lib/python3.10/site-packages/sqlalchemy/util/langhelpers.py", line 147, in __exit__
    raise exc_value.with_traceback(exc_tb)
  File "/usr/local/lib/python3.10/site-packages/sqlalchemy/pool/base.py", line 901, in __connect
    self.dbapi_connection = connection = pool._invoke_creator(self)
  File "/usr/local/lib/python3.10/site-packages/sqlalchemy/engine/create.py", line 636, in connect
    return dialect.connect(*cargs, **cparams)
  File "/usr/local/lib/python3.10/site-packages/sqlalchemy/engine/default.py", line 580, in connect
    return self.loaded_dbapi.connect(*cargs, **cparams)
  File "/usr/local/lib/python3.10/site-packages/pymysql/connections.py", line 352, in __init__
    self.connect()
  File "/usr/local/lib/python3.10/site-packages/pymysql/connections.py", line 668, in connect
    raise exc
pymysql.err.OperationalError: (2003, "Can't connect to MySQL server on 'localhost' ([Errno 99] Cannot assign requested address)")

The above exception was the direct cause of the following exception:

Traceback (most recent call last):
  File "/ReservationAPI/noshow.py", line 82, in <module>
    no_show_check = NoShowCheck()
  File "/ReservationAPI/noshow.py", line 15, in __init__
    Service.__init__(
  File "/ReservationAPI/service.py", line 180, in __init__
    self.init_orm(model_config)
  File "/ReservationAPI/service.py", line 209, in init_orm
    ORM_BASE.prepare(autoload_with=ORM_ENGINE, reflect=True)
  File "<string>", line 2, in prepare
  File "/usr/local/lib/python3.10/site-packages/sqlalchemy/util/deprecations.py", line 277, in warned
    return fn(*args, **kwargs)  # type: ignore[no-any-return]
  File "/usr/local/lib/python3.10/site-packages/sqlalchemy/ext/automap.py", line 1230, in prepare
    cls.metadata.reflect(autoload_with, **opts)  # type: ignore[arg-type]  # noqa: E501
  File "/usr/local/lib/python3.10/site-packages/sqlalchemy/sql/schema.py", line 5475, in reflect
    with inspection.inspect(bind)._inspection_context() as insp:
  File "/usr/local/lib/python3.10/site-packages/sqlalchemy/inspection.py", line 111, in inspect
    ret = reg(subject)
  File "/usr/local/lib/python3.10/site-packages/sqlalchemy/engine/reflection.py", line 304, in _engine_insp
    return Inspector._construct(Inspector._init_engine, bind)
  File "/usr/local/lib/python3.10/site-packages/sqlalchemy/engine/reflection.py", line 237, in _construct
    init(self, bind)
  File "/usr/local/lib/python3.10/site-packages/sqlalchemy/engine/reflection.py", line 248, in _init_engine
    engine.connect().close()
  File "/usr/local/lib/python3.10/site-packages/sqlalchemy/engine/base.py", line 3251, in connect
    return self._connection_cls(self)
  File "/usr/local/lib/python3.10/site-packages/sqlalchemy/engine/base.py", line 147, in __init__
    Connection._handle_dbapi_exception_noconnection(
  File "/usr/local/lib/python3.10/site-packages/sqlalchemy/engine/base.py", line 2413, in _handle_dbapi_exception_noconnection
    raise sqlalchemy_exception.with_traceback(exc_info[2]) from e
  File "/usr/local/lib/python3.10/site-packages/sqlalchemy/engine/base.py", line 145, in __init__
    self._dbapi_connection = engine.raw_connection()
  File "/usr/local/lib/python3.10/site-packages/sqlalchemy/engine/base.py", line 3275, in raw_connection
    return self.pool.connect()
  File "/usr/local/lib/python3.10/site-packages/sqlalchemy/pool/base.py", line 455, in connect
    return _ConnectionFairy._checkout(self)
  File "/usr/local/lib/python3.10/site-packages/sqlalchemy/pool/base.py", line 1271, in _checkout
    fairy = _ConnectionRecord.checkout(pool)
  File "/usr/local/lib/python3.10/site-packages/sqlalchemy/pool/base.py", line 719, in checkout
    rec = pool._do_get()
  File "/usr/local/lib/python3.10/site-packages/sqlalchemy/pool/impl.py", line 168, in _do_get
    with util.safe_reraise():
  File "/usr/local/lib/python3.10/site-packages/sqlalchemy/util/langhelpers.py", line 147, in __exit__
    raise exc_value.with_traceback(exc_tb)
  File "/usr/local/lib/python3.10/site-packages/sqlalchemy/pool/impl.py", line 166, in _do_get
    return self._create_connection()
  File "/usr/local/lib/python3.10/site-packages/sqlalchemy/pool/base.py", line 396, in _create_connection
    return _ConnectionRecord(self)
  File "/usr/local/lib/python3.10/site-packages/sqlalchemy/pool/base.py", line 681, in __init__
    self.__connect()
  File "/usr/local/lib/python3.10/site-packages/sqlalchemy/pool/base.py", line 905, in __connect
    with util.safe_reraise():
  File "/usr/local/lib/python3.10/site-packages/sqlalchemy/util/langhelpers.py", line 147, in __exit__
    raise exc_value.with_traceback(exc_tb)
  File "/usr/local/lib/python3.10/site-packages/sqlalchemy/pool/base.py", line 901, in __connect
    self.dbapi_connection = connection = pool._invoke_creator(self)
  File "/usr/local/lib/python3.10/site-packages/sqlalchemy/engine/create.py", line 636, in connect
    return dialect.connect(*cargs, **cparams)
  File "/usr/local/lib/python3.10/site-packages/sqlalchemy/engine/default.py", line 580, in connect
    return self.loaded_dbapi.connect(*cargs, **cparams)
  File "/usr/local/lib/python3.10/site-packages/pymysql/connections.py", line 352, in __init__
    self.connect()
  File "/usr/local/lib/python3.10/site-packages/pymysql/connections.py", line 668, in connect
    raise exc
sqlalchemy.exc.OperationalError: (pymysql.err.OperationalError) (2003, "Can't connect to MySQL server on 'localhost' ([Errno 99] Cannot assign requested address)")
(Background on this error at: https://sqlalche.me/e/20/e3q8)
Traceback (most recent call last):
  File "/usr/local/lib/python3.10/site-packages/pymysql/connections.py", line 616, in connect
    sock = socket.create_connection(
  File "/usr/local/lib/python3.10/socket.py", line 845, in create_connection
    raise err
  File "/usr/local/lib/python3.10/socket.py", line 833, in create_connection
    sock.connect(sa)
OSError: [Errno 99] Cannot assign requested address

During handling of the above exception, another exception occurred:

Traceback (most recent call last):
  File "/usr/local/lib/python3.10/site-packages/sqlalchemy/engine/base.py", line 145, in __init__
    self._dbapi_connection = engine.raw_connection()
  File "/usr/local/lib/python3.10/site-packages/sqlalchemy/engine/base.py", line 3275, in raw_connection
    return self.pool.connect()
  File "/usr/local/lib/python3.10/site-packages/sqlalchemy/pool/base.py", line 455, in connect
    return _ConnectionFairy._checkout(self)
  File "/usr/local/lib/python3.10/site-packages/sqlalchemy/pool/base.py", line 1271, in _checkout
    fairy = _ConnectionRecord.checkout(pool)
  File "/usr/local/lib/python3.10/site-packages/sqlalchemy/pool/base.py", line 719, in checkout
    rec = pool._do_get()
  File "/usr/local/lib/python3.10/site-packages/sqlalchemy/pool/impl.py", line 168, in _do_get
    with util.safe_reraise():
  File "/usr/local/lib/python3.10/site-packages/sqlalchemy/util/langhelpers.py", line 147, in __exit__
    raise exc_value.with_traceback(exc_tb)
  File "/usr/local/lib/python3.10/site-packages/sqlalchemy/pool/impl.py", line 166, in _do_get
    return self._create_connection()
  File "/usr/local/lib/python3.10/site-packages/sqlalchemy/pool/base.py", line 396, in _create_connection
    return _ConnectionRecord(self)
  File "/usr/local/lib/python3.10/site-packages/sqlalchemy/pool/base.py", line 681, in __init__
    self.__connect()
  File "/usr/local/lib/python3.10/site-packages/sqlalchemy/pool/base.py", line 905, in __connect
    with util.safe_reraise():
  File "/usr/local/lib/python3.10/site-packages/sqlalchemy/util/langhelpers.py", line 147, in __exit__
    raise exc_value.with_traceback(exc_tb)
  File "/usr/local/lib/python3.10/site-packages/sqlalchemy/pool/base.py", line 901, in __connect
    self.dbapi_connection = connection = pool._invoke_creator(self)
  File "/usr/local/lib/python3.10/site-packages/sqlalchemy/engine/create.py", line 636, in connect
    return dialect.connect(*cargs, **cparams)
  File "/usr/local/lib/python3.10/site-packages/sqlalchemy/engine/default.py", line 580, in connect
    return self.loaded_dbapi.connect(*cargs, **cparams)
  File "/usr/local/lib/python3.10/site-packages/pymysql/connections.py", line 352, in __init__
    self.connect()
  File "/usr/local/lib/python3.10/site-packages/pymysql/connections.py", line 668, in connect
    raise exc
pymysql.err.OperationalError: (2003, "Can't connect to MySQL server on 'localhost' ([Errno 99] Cannot assign requested address)")

The above exception was the direct cause of the following exception:

Traceback (most recent call last):
  File "/ReservationAPI/noshow.py", line 82, in <module>
    no_show_check = NoShowCheck()
  File "/ReservationAPI/noshow.py", line 15, in __init__
    Service.__init__(
  File "/ReservationAPI/service.py", line 180, in __init__
    self.init_orm(model_config)
  File "/ReservationAPI/service.py", line 209, in init_orm
    ORM_BASE.prepare(autoload_with=ORM_ENGINE, reflect=True)
  File "<string>", line 2, in prepare
  File "/usr/local/lib/python3.10/site-packages/sqlalchemy/util/deprecations.py", line 277, in warned
    return fn(*args, **kwargs)  # type: ignore[no-any-return]
  File "/usr/local/lib/python3.10/site-packages/sqlalchemy/ext/automap.py", line 1230, in prepare
    cls.metadata.reflect(autoload_with, **opts)  # type: ignore[arg-type]  # noqa: E501
  File "/usr/local/lib/python3.10/site-packages/sqlalchemy/sql/schema.py", line 5475, in reflect
    with inspection.inspect(bind)._inspection_context() as insp:
  File "/usr/local/lib/python3.10/site-packages/sqlalchemy/inspection.py", line 111, in inspect
    ret = reg(subject)
  File "/usr/local/lib/python3.10/site-packages/sqlalchemy/engine/reflection.py", line 304, in _engine_insp
    return Inspector._construct(Inspector._init_engine, bind)
  File "/usr/local/lib/python3.10/site-packages/sqlalchemy/engine/reflection.py", line 237, in _construct
    init(self, bind)
  File "/usr/local/lib/python3.10/site-packages/sqlalchemy/engine/reflection.py", line 248, in _init_engine
    engine.connect().close()
  File "/usr/local/lib/python3.10/site-packages/sqlalchemy/engine/base.py", line 3251, in connect
    return self._connection_cls(self)
  File "/usr/local/lib/python3.10/site-packages/sqlalchemy/engine/base.py", line 147, in __init__
    Connection._handle_dbapi_exception_noconnection(
  File "/usr/local/lib/python3.10/site-packages/sqlalchemy/engine/base.py", line 2413, in _handle_dbapi_exception_noconnection
    raise sqlalchemy_exception.with_traceback(exc_info[2]) from e
  File "/usr/local/lib/python3.10/site-packages/sqlalchemy/engine/base.py", line 145, in __init__
    self._dbapi_connection = engine.raw_connection()
  File "/usr/local/lib/python3.10/site-packages/sqlalchemy/engine/base.py", line 3275, in raw_connection
    return self.pool.connect()
  File "/usr/local/lib/python3.10/site-packages/sqlalchemy/pool/base.py", line 455, in connect
    return _ConnectionFairy._checkout(self)
  File "/usr/local/lib/python3.10/site-packages/sqlalchemy/pool/base.py", line 1271, in _checkout
    fairy = _ConnectionRecord.checkout(pool)
  File "/usr/local/lib/python3.10/site-packages/sqlalchemy/pool/base.py", line 719, in checkout
    rec = pool._do_get()
  File "/usr/local/lib/python3.10/site-packages/sqlalchemy/pool/impl.py", line 168, in _do_get
    with util.safe_reraise():
  File "/usr/local/lib/python3.10/site-packages/sqlalchemy/util/langhelpers.py", line 147, in __exit__
    raise exc_value.with_traceback(exc_tb)
  File "/usr/local/lib/python3.10/site-packages/sqlalchemy/pool/impl.py", line 166, in _do_get
    return self._create_connection()
  File "/usr/local/lib/python3.10/site-packages/sqlalchemy/pool/base.py", line 396, in _create_connection
    return _ConnectionRecord(self)
  File "/usr/local/lib/python3.10/site-packages/sqlalchemy/pool/base.py", line 681, in __init__
    self.__connect()
  File "/usr/local/lib/python3.10/site-packages/sqlalchemy/pool/base.py", line 905, in __connect
    with util.safe_reraise():
  File "/usr/local/lib/python3.10/site-packages/sqlalchemy/util/langhelpers.py", line 147, in __exit__
    raise exc_value.with_traceback(exc_tb)
  File "/usr/local/lib/python3.10/site-packages/sqlalchemy/pool/base.py", line 901, in __connect
    self.dbapi_connection = connection = pool._invoke_creator(self)
  File "/usr/local/lib/python3.10/site-packages/sqlalchemy/engine/create.py", line 636, in connect
    return dialect.connect(*cargs, **cparams)
  File "/usr/local/lib/python3.10/site-packages/sqlalchemy/engine/default.py", line 580, in connect
    return self.loaded_dbapi.connect(*cargs, **cparams)
  File "/usr/local/lib/python3.10/site-packages/pymysql/connections.py", line 352, in __init__
    self.connect()
  File "/usr/local/lib/python3.10/site-packages/pymysql/connections.py", line 668, in connect
    raise exc
sqlalchemy.exc.OperationalError: (pymysql.err.OperationalError) (2003, "Can't connect to MySQL server on 'localhost' ([Errno 99] Cannot assign requested address)")
(Background on this error at: https://sqlalche.me/e/20/e3q8)
Traceback (most recent call last):
  File "/usr/local/lib/python3.10/site-packages/pymysql/connections.py", line 616, in connect
    sock = socket.create_connection(
  File "/usr/local/lib/python3.10/socket.py", line 845, in create_connection
    raise err
  File "/usr/local/lib/python3.10/socket.py", line 833, in create_connection
    sock.connect(sa)
OSError: [Errno 99] Cannot assign requested address

During handling of the above exception, another exception occurred:

Traceback (most recent call last):
  File "/usr/local/lib/python3.10/site-packages/sqlalchemy/engine/base.py", line 145, in __init__
    self._dbapi_connection = engine.raw_connection()
  File "/usr/local/lib/python3.10/site-packages/sqlalchemy/engine/base.py", line 3275, in raw_connection
    return self.pool.connect()
  File "/usr/local/lib/python3.10/site-packages/sqlalchemy/pool/base.py", line 455, in connect
    return _ConnectionFairy._checkout(self)
  File "/usr/local/lib/python3.10/site-packages/sqlalchemy/pool/base.py", line 1271, in _checkout
    fairy = _ConnectionRecord.checkout(pool)
  File "/usr/local/lib/python3.10/site-packages/sqlalchemy/pool/base.py", line 719, in checkout
    rec = pool._do_get()
  File "/usr/local/lib/python3.10/site-packages/sqlalchemy/pool/impl.py", line 168, in _do_get
    with util.safe_reraise():
  File "/usr/local/lib/python3.10/site-packages/sqlalchemy/util/langhelpers.py", line 147, in __exit__
    raise exc_value.with_traceback(exc_tb)
  File "/usr/local/lib/python3.10/site-packages/sqlalchemy/pool/impl.py", line 166, in _do_get
    return self._create_connection()
  File "/usr/local/lib/python3.10/site-packages/sqlalchemy/pool/base.py", line 396, in _create_connection
    return _ConnectionRecord(self)
  File "/usr/local/lib/python3.10/site-packages/sqlalchemy/pool/base.py", line 681, in __init__
    self.__connect()
  File "/usr/local/lib/python3.10/site-packages/sqlalchemy/pool/base.py", line 905, in __connect
    with util.safe_reraise():
  File "/usr/local/lib/python3.10/site-packages/sqlalchemy/util/langhelpers.py", line 147, in __exit__
    raise exc_value.with_traceback(exc_tb)
  File "/usr/local/lib/python3.10/site-packages/sqlalchemy/pool/base.py", line 901, in __connect
    self.dbapi_connection = connection = pool._invoke_creator(self)
  File "/usr/local/lib/python3.10/site-packages/sqlalchemy/engine/create.py", line 636, in connect
    return dialect.connect(*cargs, **cparams)
  File "/usr/local/lib/python3.10/site-packages/sqlalchemy/engine/default.py", line 580, in connect
    return self.loaded_dbapi.connect(*cargs, **cparams)
  File "/usr/local/lib/python3.10/site-packages/pymysql/connections.py", line 352, in __init__
    self.connect()
  File "/usr/local/lib/python3.10/site-packages/pymysql/connections.py", line 668, in connect
    raise exc
pymysql.err.OperationalError: (2003, "Can't connect to MySQL server on 'localhost' ([Errno 99] Cannot assign requested address)")

The above exception was the direct cause of the following exception:

Traceback (most recent call last):
  File "/ReservationAPI/noshow.py", line 82, in <module>
    no_show_check = NoShowCheck()
  File "/ReservationAPI/noshow.py", line 15, in __init__
    Service.__init__(
  File "/ReservationAPI/service.py", line 180, in __init__
    self.init_orm(model_config)
  File "/ReservationAPI/service.py", line 209, in init_orm
    ORM_BASE.prepare(autoload_with=ORM_ENGINE, reflect=True)
  File "<string>", line 2, in prepare
  File "/usr/local/lib/python3.10/site-packages/sqlalchemy/util/deprecations.py", line 277, in warned
    return fn(*args, **kwargs)  # type: ignore[no-any-return]
  File "/usr/local/lib/python3.10/site-packages/sqlalchemy/ext/automap.py", line 1230, in prepare
    cls.metadata.reflect(autoload_with, **opts)  # type: ignore[arg-type]  # noqa: E501
  File "/usr/local/lib/python3.10/site-packages/sqlalchemy/sql/schema.py", line 5475, in reflect
    with inspection.inspect(bind)._inspection_context() as insp:
  File "/usr/local/lib/python3.10/site-packages/sqlalchemy/inspection.py", line 111, in inspect
    ret = reg(subject)
  File "/usr/local/lib/python3.10/site-packages/sqlalchemy/engine/reflection.py", line 304, in _engine_insp
    return Inspector._construct(Inspector._init_engine, bind)
  File "/usr/local/lib/python3.10/site-packages/sqlalchemy/engine/reflection.py", line 237, in _construct
    init(self, bind)
  File "/usr/local/lib/python3.10/site-packages/sqlalchemy/engine/reflection.py", line 248, in _init_engine
    engine.connect().close()
  File "/usr/local/lib/python3.10/site-packages/sqlalchemy/engine/base.py", line 3251, in connect
    return self._connection_cls(self)
  File "/usr/local/lib/python3.10/site-packages/sqlalchemy/engine/base.py", line 147, in __init__
    Connection._handle_dbapi_exception_noconnection(
  File "/usr/local/lib/python3.10/site-packages/sqlalchemy/engine/base.py", line 2413, in _handle_dbapi_exception_noconnection
    raise sqlalchemy_exception.with_traceback(exc_info[2]) from e
  File "/usr/local/lib/python3.10/site-packages/sqlalchemy/engine/base.py", line 145, in __init__
    self._dbapi_connection = engine.raw_connection()
  File "/usr/local/lib/python3.10/site-packages/sqlalchemy/engine/base.py", line 3275, in raw_connection
    return self.pool.connect()
  File "/usr/local/lib/python3.10/site-packages/sqlalchemy/pool/base.py", line 455, in connect
    return _ConnectionFairy._checkout(self)
  File "/usr/local/lib/python3.10/site-packages/sqlalchemy/pool/base.py", line 1271, in _checkout
    fairy = _ConnectionRecord.checkout(pool)
  File "/usr/local/lib/python3.10/site-packages/sqlalchemy/pool/base.py", line 719, in checkout
    rec = pool._do_get()
  File "/usr/local/lib/python3.10/site-packages/sqlalchemy/pool/impl.py", line 168, in _do_get
    with util.safe_reraise():
  File "/usr/local/lib/python3.10/site-packages/sqlalchemy/util/langhelpers.py", line 147, in __exit__
    raise exc_value.with_traceback(exc_tb)
  File "/usr/local/lib/python3.10/site-packages/sqlalchemy/pool/impl.py", line 166, in _do_get
    return self._create_connection()
  File "/usr/local/lib/python3.10/site-packages/sqlalchemy/pool/base.py", line 396, in _create_connection
    return _ConnectionRecord(self)
  File "/usr/local/lib/python3.10/site-packages/sqlalchemy/pool/base.py", line 681, in __init__
    self.__connect()
  File "/usr/local/lib/python3.10/site-packages/sqlalchemy/pool/base.py", line 905, in __connect
    with util.safe_reraise():
  File "/usr/local/lib/python3.10/site-packages/sqlalchemy/util/langhelpers.py", line 147, in __exit__
    raise exc_value.with_traceback(exc_tb)
  File "/usr/local/lib/python3.10/site-packages/sqlalchemy/pool/base.py", line 901, in __connect
    self.dbapi_connection = connection = pool._invoke_creator(self)
  File "/usr/local/lib/python3.10/site-packages/sqlalchemy/engine/create.py", line 636, in connect
    return dialect.connect(*cargs, **cparams)
  File "/usr/local/lib/python3.10/site-packages/sqlalchemy/engine/default.py", line 580, in connect
    return self.loaded_dbapi.connect(*cargs, **cparams)
  File "/usr/local/lib/python3.10/site-packages/pymysql/connections.py", line 352, in __init__
    self.connect()
  File "/usr/local/lib/python3.10/site-packages/pymysql/connections.py", line 668, in connect
    raise exc
sqlalchemy.exc.OperationalError: (pymysql.err.OperationalError) (2003, "Can't connect to MySQL server on 'localhost' ([Errno 99] Cannot assign requested address)")
(Background on this error at: https://sqlalche.me/e/20/e3q8)
{'username': None, 'password': None, 'host': None, 'port': None, 'database': None} {'get_auth_info': 'http://userservice:5000/auth/jwt-status', 'increment_noshow': 'http://userservice:5000/users/{user_id}/no-show', 'get_rooms_info': 'http://managementservice:5000/admin/rooms/{id}', 'send_email': 'http://alertservice:5000/alert'}
=================running cronjob=====================
updating noshow counts for {}
{'username': None, 'password': None, 'host': None, 'port': None, 'database': None} {'get_auth_info': 'http://userservice:5000/auth/jwt-status', 'increment_noshow': 'http://userservice:5000/users/{user_id}/no-show', 'get_rooms_info': 'http://managementservice:5000/admin/rooms/{id}', 'send_email': 'http://alertservice:5000/alert'}
=================running cronjob=====================
updating noshow counts for {}
{'username': None, 'password': None, 'host': None, 'port': None, 'database': None} {'get_auth_info': 'http://userservice:5000/auth/jwt-status', 'increment_noshow': 'http://userservice:5000/users/{user_id}/no-show', 'get_rooms_info': 'http://managementservice:5000/admin/rooms/{id}', 'send_email': 'http://alertservice:5000/alert'}
=================running cronjob=====================
updating noshow counts for {}
{'username': None, 'password': None, 'host': None, 'port': None, 'database': None} {'get_auth_info': 'http://userservice:5000/auth/jwt-status', 'increment_noshow': 'http://userservice:5000/users/{user_id}/no-show', 'get_rooms_info': 'http://managementservice:5000/admin/rooms/{id}', 'send_email': 'http://alertservice:5000/alert'}
=================running cronjob=====================
updating noshow counts for {}
{'username': None, 'password': None, 'host': None, 'port': None, 'database': None} {'get_auth_info': 'http://userservice:5000/auth/jwt-status', 'increment_noshow': 'http://userservice:5000/users/{user_id}/no-show', 'get_rooms_info': 'http://managementservice:5000/admin/rooms/{id}', 'send_email': 'http://alertservice:5000/alert'}
=================running cronjob=====================
updating noshow counts for {}
